Workbook

Sheet Checker
A1: Domains | B1: Present Lines | C1: Missing Lines | D1: Account Manager | G1: Required Lines
A2: mollygram.com | B2: google.com, pub-7094677798399606, RESELLER, f08c47fec0942fa0 google.com, pub-2403018226404213, RESELLER, f08c47fec0942fa0 tapmind.com, TMP10227, DIRECT google.com, pub-1714061154748628, RESELLER, f08c47fec0942fa0 google.com, pub-8686615022940025, RESELLER, f08c47fec0942fa0 kickads.mobi, 62, DIRECT google.com, pub-2915053785761950, RESELLER, f08c47fec0942fa0 headerbiddr.com, 127, DIRECT google.com, pub-6254331789601537, RESELLER, f08c47fec0942fa0 rtbdemand.com, 22872606502, DIRECT google.com, pub-3872674820285626, RESELLER, f08c47fec0942fa0 adipolo.com, 23050223808, DIRECT adipolosolutions.com, 23050223808, DIRECT pmbmonetize.com, 23050223808, DIRECT opamarketplace.com, 23050223808, DIRECT google.com, pub-2930805104418204, RESELLER, f08c47fec0942fa0 google.com, pub-4903453974745530, RESELLER, f08c47fec0942fa0 google.com, pub-4836542095728076, RESELLER, f08c47fec0942fa0 google.com, pub-9135355251665930, RESELLER, f08c47fec0942fa0 google.com, pub-6804276076764268, RESELLER, f08c47fec0942fa0 smartadline.com, 23073759535, DIRECT gannett.com, 22675194701, DIRECT google.com, pub-5717092533913515, RESELLER, f08c47fec0942fa0 sharethrough.com, Bc6D1WHS, RESELLER, d53b998a7bd4ecd2 richaudience.com, q3KyMB36ue, RESELLER contextweb.com, 562726, RESELLER, 89ff185a4c4e857c loopme.com, 11561, RESELLER, 6c8d5f95897a5a3b inmobi.com, ef083d721beb4c0f8776ced01e262c03, RESELLER, 83e75a7ae333ca9d onetag.com, 82bad7d17eccf7c, RESELLER lijit.com, 276595, DIRECT, fafdf38b16bf6b2b #SOVRN lijit.com, 276595-eb, DIRECT, fafdf38b16bf6b2b #SOVRN openx.com, 538959099, RESELLER, 6a698e2ec38604c6 pubmatic.com, 137711, RESELLER, 5d62403b186f2ace pubmatic.com, 156212, RESELLER, 5d62403b186f2ace rubiconproject.com, 17960, RESELLER, 0bfd66d529a55807 appnexus.com, 1019, RESELLER, f5ab79cb980f11d1 video.unrulymedia.com, 2444764291, RESELLER krushmedia.com, AJxF6R572a9M6CaTvK, RESELLER motorik.io, 100463, RESELLER smaato.com, 1100056344, RESELLER, 07bcf65f187117b4 smartadserver.com, 4926, RESELLER, 060d053dcf45cbf3 aniview.com, 68caaf49b07702ddc30e5038, RESELLER, 78b21b97965ec3f8 gannett.com, 22652678936, RESELLER, dd61c0c3f57b6942 pubmatic.com, 160993, RESELLER, 5d62403b186f2ace rubiconproject.com, 13918, RESELLER, 0bfd66d529a55807 richaudience.com, 1ru8dKmJJV, RESELLER rubiconproject.com, 13510, RESELLER, 0bfd66d529a55807 pubmatic.com, 81564, RESELLER, 5d62403b186f2ace pubmatic.com, 156538, RESELLER, 5d62403b186f2ace playstream.media, 911, RESELLER google.com, pub-4586415728471297, RESELLER, f08c47fec0942fa0 google.com, pub-8584156348842922, RESELLER, f08c47fec0942fa0 google.com, pub-3565385483761681, RESELLER, f08c47fec0942fa0 didna.io, 22652678936, RESELLER pubmatic.com, 160107, RESELLER, 5d62403b186f2ace inmobi.com, 155796dfff86494e9b375346a748e8eb, RESELLER, 83e75a7ae333ca9d lijit.com, 376385, RESELLER, fafdf38b16bf6b2b onetag.com, 57e618150c70d90, RESELLER google.com, pub-6479999173277695, RESELLER, f08c47fec0942fa0 media.net, 8CU322PTV, RESELLER, 818f58666cabc936 appnexus.com, 12637, RESELLER, f5ab79cb980f11d1 monetizemore.com, dd695c8dde, DIRECT google.com, pub-5278973888786334, reseller, f08c47fec0942fa0 google.com, pub-6190096338979886, reseller, f08c47fec0942fa0 target-video.com, 330, DIRECT google.com, pub-7114971906786170, RESELLER, f08c47fec0942fa0 pubmatic.com, 161997, RESELLER, 5d62403b186f2ace pubmatic.com, 161656, RESELLER, 5d62403b186f2ace improvedigital.com, 2098, RESELLER improvedigital.com, 2192, RESELLER triplelift.com, 14190-EB, RESELLER, 6c33edb13117fd86 triplelift.com, 14190, RESELLER, 6c33edb13117fd86 yieldlab.net, 10710236, RESELLER yieldlab.net, 2172218, RESELLER yieldlab.net, 227224, RESELLER yieldlab.net, 506261, RESELLER yieldlab.net, 6374282, RESELLER indexexchange.com, 191771, RESELLER, 50b1c356f2c5c8fc openx.com, 539246483, RESELLER pubmatic.com, 158858, RESELLER, 5d62403b186f2ace appnexus.com, 13424, RESELLER, f5ab79cb980f11d1 sspx.tech, dspx77, DIRECT adform.com,3001,RESELLER pubmatic.com,163037,RESELLER rubiconproject.com,25488,RESELLER yieldlab.net,14540899,RESELLER yieldlab.net,227224,RESELLER adform.com, 3126, RESELLER freewheel.tv, 1598760, DIRECT freewheel.tv, 1598816, RESELLER rubiconproject.com, 22862, RESELLER, 0bfd66d529a55807 smartadserver.com, 4173-OB, RESELLER, 060d053dcf45cbf3 lijit.com, 374714, RESELLER, fafdf38b16bf6b2b openx.com, 556576533, RESELLER, 6a698e2ec38604c6 video.unrulymedia.com, 695644456, RESELLER onetag.com, 79b477c31000ac4-OB, RESELLER appnexus.com, 13099, RESELLER pubmatic.com, 161593, RESELLER, 5d62403b186f2ace freewheel.tv, 20393, RESELLER freewheel.tv, 24377, RESELLER rubiconproject.com, 11006, RESELLER, 0bfd66d529a55807 sharethrough.com, 6Hhup0n5, RESELLER, d53b998a7bd4ecd2 themediagrid.com, DAQTOP, DIRECT, 35d5010d7789b49d themediagrid.com, D9CE4A, DIRECT, 35d5010d7789b49d adagio.io, 1442, RESELLER rubiconproject.com, 19116, RESELLER, 0bfd66d529a55807 pubmatic.com, 159110, RESELLER, 5d62403b186f2ace improvedigital.com, 1790, RESELLER onetag.com, 6b859b96c564fbe, RESELLER 33across.com, 0015a00002oUk4aAAC, RESELLER, bbea06d9c4d2853c smartadserver.com, 3554, RESELLER loopme.com, 5679, RESELLER, 6c8d5f95897a5a3b sharethrough.com, OAW69Fon, RESELLER, d53b998a7bd4ecd2 lijit.com, 367236, RESELLER, fafdf38b16bf6b2b freewheel.tv, 1568036, RESELLER freewheel.tv, 1568041, RESELLER openx.com, 558899373, RESELLER, 6a698e2ec38604c6 triplelift.com, 13482, RESELLER, 6c33edb13117fd86 e-planning.net, 83c06e81531537f4, RESELLER, c1ba615865ed87b2 rubiconproject.com, 12186, RESELLER, 0bfd66d529a55807 zetaglobal.net, 891, RESELLER appnexus.com, 15941, RESELLER video.unrulymedia.com, 5672421953199218469, RESELLER admanmedia.com, 2216, RESELLER connectad.io, 456, RESELLER, 85ac85a30c93b3e5 rubiconproject.com, 26800, RESELLER, 0bfd66d529a55807 insticator.com, 4ec3ed85-2830-4174-9f7f-f545620598b9, RESELLER, b3511ffcafb23a32 sharethrough.com, Q9IzHdvp, RESELLER, d53b998a7bd4ecd2 kueez.com, 204794845b2574bb9d18fb5f94c9ec85, reseller appnexus.com,8826,reseller rubiconproject.com,16920,reseller openx.com, 557564833, RESELLER, 6a698e2ec38604c6 lijit.com,407406,reseller media.net,8cu4jtrf9,reseller pubmatic.com,162110,reseller sharethrough.com,n98xdzel,reseller 33across.com, 0010b00002ODU4HAAX,reseller, bbea06d9c4d2853c yieldmo.com,3133660606033240149,reseller onetag.com,6e053d779444c00,reseller video.unrulymedia.com,3486482593,reseller sonobi.com,4c4fba1717,reseller smartadserver.com,4288,reseller zetaglobal.com,108,reseller improvedigital.com,2106,reseller adform.com,2926,reseller start.io, 185522363, reseller loopme.com,11576,reseller themediagrid.com,uot45z,reseller trustedstack.com, TSIO6G4I5, reseller risecodes.com, 670135d2e64cee0001b3f010, DIRECT sharethrough.com, 5926d422, RESELLER, d53b998a7bd4ecd2 pubmatic.com, 160295, RESELLER, 5d62403b186f2ace rubiconproject.com, 23876, RESELLER, 0bfd66d529a55807 xandr.com, 14082, RESELLER media.net, 8CUQ6928Q, RESELLER lijit.com, 405318, RESELLER, fafdf38b16bf6b2b yieldmo.com, 2754490424016969782, RESELLER video.unrulymedia.com, 335119963, RESELLER smaato.com, 1100057444, RESELLER, 07bcf65f187117b4 33across.com, 0010b00002Xbn7QAAR, RESELLER, bbea06d9c4d2853c loopme.com, 11362, RESELLER, 6c8d5f95897a5a3b onetag.com, 69f48c2160c8113, RESELLER openx.com, 537140488, RESELLER, 6a698e2ec38604c6 smartadserver.com, 4284, RESELLER inmobi.com, 9e311c7a68e94888aac7fbb4272381e2, RESELLER, 83e75a7ae333ca9d themediagrid.com, 4DQHAP, RESELLER, 35d5010d7789b49d themediagrid.com, HW1PGR, RESELLER, 35d5010d7789b49d amxrtb.com, 105199691, RESELLER contextweb.com,562615,RESELLER,89ff185a4c4e857c adform.com, 3119, RESELLER, 9f5210a2f0999e32 adyoulike.com, 78afbc34fac571736717317117dfa247, RESELLER gumgum.com, 16112, RESELLER, ffdef49475d318a9 zetaglobal.net, 716, RESELLER freewheel.tv, 1590601, RESELLER freewheel.tv, 1590606, RESELLER video.unrulymedia.com, 612539011, RESELLER pubmatic.com, 159277, RESELLER appnexus.com, 6849, RESELLER xad.com, 963, RESELLER, 81cbf0a75a5e0e9a openx.com, 543878511, RESELLER, 6a698e2ec38604c6 smaato.com, 1100047589, RESELLER, 07bcf65f187117b4 inmobi.com, ba5fd3fb82c5412989b23c3eec71baf7, RESELLER, 83e75a7ae333ca9d improvedigital.com, 1699, RESELLER video.unrulymedia.com, 568368565, RESELLER datawrkz.com, 2218, DIRECT datawrkz.com, 2394, DIRECT google.com, pub-8856559311549217, RESELLER, f08c47fec0942fa0 google.com, pub-6645287046856849, DIRECT, f08c47fec0942fa0 thegermanemedia.com,407, RESELLER, 6716225838534735 google.com, pub-6716225838534735, RESELLER, f08c47fec0942fa0 streamlyn.com, bsrvptr20157, RESELLER vidgyor.com, 30000, RESELLER google.com, pub-8863191426564274, RESELLER, f08c47fec0942fa0 incrementx.com, 50003, DIRECT, 8728b7e97e589da4 google.com, pub-3977122154505186, RESELLER, f08c47fec0942fa0 rtbdemand.com, 22849693057, RESELLER openx.com, 561447216, RESELLER, 6a698e2ec38604c6 google.com, pub-3990748024667386, RESELLER, f08c47fec0942fa0 google.com, pub-8431644635469171, DIRECT, f08c47fec0942fa0 pubmatic.com, 161652, DIRECT, 5d62403b186f2ace onetag.com, 774083553572acc, DIRECT inmobi.com, 64390d9c0d0541bc9b06ab42a124b396, DIRECT, 83e75a7ae333ca9d nexverse.ai, 24099, DIRECT bidmatic.io, b-b54fe, DIRECT adtelligent.com, 742654, DIRECT, 8ce87912eb022a51 vidoomy.com, 8804284, RESELLER pubmatic.com, 156498, RESELLER, 5d62403b186f2ace rubiconproject.com, 26884, DIRECT, 0bfd66d529a55807 conversantmedia.com, 100789, RESELLER, 03113cd04947736d 152media.info, 152M698, RESELLER admanmedia.com, 2050, RESELLER appnexus.com, 4052, RESELLER e-planning.net, 1bf7b5d803f178c4, RESELLER, c1ba615865ed87b2 lijit.com, 411121, RESELLER, fafdf38b16bf6b2b openx.com, 540031703, RESELLER, 6a698e2ec38604c6 pubmatic.com, 158100, RESELLER, 5d62403b186f2ace rubiconproject.com, 23644, RESELLER, 0bfd66d529a55807 smartyads.com, 300045, RESELLER, fd2bde0ff2e62c5d video.unrulymedia.com, 645663965, RESELLER yahoo.com, 55771, RESELLER, e1a5b5b6e3255540 smilewanted.com, 3440, RESELLER pubmatic.com, 158810, RESELLER, 5d62403b186f2ace appnexus.com, 10040, RESELLER smartadserver.com, 2491, RESELLER rubiconproject.com, 19814, RESELLER, 0bfd66d529a55807 lijit.com, 346012, RESELLER, fafdf38b16bf6b2b video.unrulymedia.com, 1767448067723954599, RESELLER openx.com, 557083110, RESELLER, 6a698e2ec38604c6 sharethrough.com, TZ1ahFV8, RESELLER, d53b998a7bd4ecd2 adform.com, 3027, RESELLER loopme.com, 11468, RESELLER, 6c8d5f95897a5a3b 33across.com, 001Pg000009Gtq2IAC, RESELLER, bbea06d9c4d2853c onetag.com, 7f5d22b0006ab5a, RESELLER themediagrid.com, ZG1DBN, RESELLER, 35d5010d7789b49d videoheroes.tv, 212648, RESELLER , 064bc410192443d8 betweendigital.com, 45128, RESELLER admanmedia.com, 2281, RESELLER improvedigital.com, 1010, RESELLER amxrtb.com, 105199841, RESELLER rubiconproject.com, 27408, DIRECT, 0bfd66d529a55807 152media.info, 152M166, RESELLER appnexus.com, 3153, RESELLER, f5ab79cb980f11d1 appnexus.com, 11924, RESELLER, f5ab79cb980f11d1 xandr.com, 11924, RESELLER, f5ab79cb980f11d1 jambojar.com, 2024J1326, DIRECT Ads-mesh.com, adm-2024J1326, DIRECT google.com, pub-5348345762832984, DIRECT, f08c47fec0942fa0 google.com, pub-9084396328078500, DIRECT, f08c47fec0942fa0 google.com, pub-6914523826711866, DIRECT, f08c47fec0942fa0 google.com, pub-7119804600138686, DIRECT, f08c47fec0942fa0 google.com, pub-7471191098316515, DIRECT, f08c47fec0942fa0 google.com, pub-7167853774941043, DIRECT, f08c47fec0942fa0 inmobi.com, 1386c3283cdf43c687c7e433c94b4eaa, RESELLER, 83e75a7ae333ca9d Pubmatic.com, 159941, DIRECT pubmatic.com, 166238, DIRECT, 5d62403b186f2ace openx.com, 562388597, RESELLER, 6a698e2ec38604c6 rubiconproject.com, 24872, DIRECT rubiconproject.com, 24872, RESELLER, 0bfd66d529a55807 adsolut.in, 30010, Direct google.com, pub-8584156348842922, DIRECT, f08c47fec0942fa0 google.com, pub-9119026932363247, DIRECT, f08c47fec0942fa0 google.com, pub-1615310408372741, DIRECT, f08c47fec0942fa0 rubiconproject.com, 24874, RESELLER, 0bfd66d529a55807 rubiconproject.com, 26768, RESELLER, 0bfd66d529a55807 themediagrid.com, Q6VXLE, DIRECT, 35d5010d7789b49d freewheel.tv, 1599079, DIRECT freewheel.tv, 1599080, RESELLER 152media.info,152M1051,RESELLER smilewanted.com, 3784, RESELLER adwmg.com, 100213, DIRECT, c9688a22012618e7 google.com, pub-8622186303703569, DIRECT, f08c47fec0942fa0 google.com, pub-8309773808661346, RESELLER, f08c47fec0942fa0 bidfuse.com, bf-6288, DIRECT google.com, pub-6151720204273327, RESELLER, f08c47fec0942fa0 copper6.com, 766168, DIRECT Carliba.io, 184069, DIRECT aps.amazon.com, ec4e8edf-c46b-44a1-bcab-17b3a4420b9a, RESELLER google.com, pub-9966039342650298, RESELLER, f08c47fec0942fa0 rubiconproject.com, 26360, RESELLER, 0bfd66d529a55807 video.unrulymedia.com, 449519254, RESELLER Xandr.com, 16546, RESELLER Media.net, 8CU377B3G, RESELLER adingo.jp, 32948, RESELLER openx.com, 563905670, DIRECT, 6a698e2ec38604c6 adyoulike.com, a40a86ea548b729fc92e98b618536ba1, RESELLER onetag.com, 8bd233947b607f0, RESELLER themediagrid.com, VM75KS, DIRECT, 35d5010d7789b49d inmobi.com, 541fff38bbaf4047be082d9ca66242fa, RESELLER, 83e75a7ae333ca9d nativo.com, 5960, RESELLER, 59521ca7cc5e9fee pubmatic.com, 164798, RESELLER, 5d62403b186f2ace pubmatic.com, 165854, RESELLER, 5d62403b186f2ace seedtag.com, 67feadce79a77d0007b698a5, RESELLER smartadserver.com, 5086, RESELLER, 060d053dcf45cbf3 aps.amazon.com, d4004b5f-4fb6-4be2-82ae-0e36b8f52c12, RESELLER sonobi.com, a0ece019ba, RESELLER, d1a215d9eb5aee9e sonobi.com, 79e197cdbc, RESELLER, d1a215d9eb5aee9e conversantmedia.com, 100693, RESELLER, 03113cd04947736d richaudience.com, twnG2qCkBd, RESELLER lijit.com, 503539, RESELLER, fafdf38b16bf6b2b improvedigital.com, 2556, RESELLER amxrtb.com, 105199329, DIRECT smilewanted.com, 5625, RESELLER consumable.com, 2001634, RESELLER, aefcd3d2f45b5070 beachfront.com, 15250, RESELLER, e2541279e8e2ca4d app-stock.com, 145567, RESELLER, ed8c126ea5971415 triplelift.com, 12884, RESELLER, 6c33edb13117fd86 152media.info,152M768, RESELLER Smartbid.ai, 3206651, DIRECT freewheel.tv, 1608878, RESELLER freewheel.tv, 1608885, RESELLER richaudience.com, 1fsNorHWpU, RESELLER appnexus.com, 8233, RESELLER rubiconproject.com, 13510, RESELLER adform.com, 1942, RESELLER lijit.com, 249425, RESELLER video.unrulymedia.com, 592728597, RESELLER smartadserver.com, 2640, RESELLER adyoulike.com, f1dfbb7f133fbdb25c96e7d85a5e628b, RESELLER themediagrid.com, P19GFJ, RESELLER, 35d5010d7789b49d smartadserver.com, 1999, RESELLER, 060d053dcf45cbf3 onetag.com, 8d4b087143c49f0, RESELLER amxrtb.com, 105199794, RESELLER contextweb.com, 563371, RESELLER, 89ff185a4c4e857c onetag.com, 7a4244b2979db22, RESELLER onetag.com, 7a4244b2979db22-OB, RESELLER openx.com, 539625136, RESELLER google.com, pub-2128757167812663, RESELLER, f08c47fec0942fa0 google.com, pub-4673227357197067, RESELLER, f08c47fec0942fa0 rubiconproject.com, 17210, RESELLER, 0bfd66d529a55807 appnexus.com, 10264, RESELLER, f5ab79cb980f11d1 pubmatic.com, 156383, RESELLER, 5d62403b186f2ace themediagrid.com, VIY354, RESELLER, 35d5010d7789b49d smartadserver.com, 1743, RESELLER, 060d053dcf45cbf3 improvedigital.com, 2048, RESELLER lijit.com, 257429, RESELLER, fafdf38b16bf6b2b adform.com, 2474, RESELLER, 9f5210a2f0999e32 triplelift.com, 12911, RESELLER, 6c33edb13117fd86 aps.amazon.com, 93aec77c-f6d2-45bd-affc-a85ab5a72683, RESELLER onetag.com, 59817ac704fe3e8, RESELLER betweendigital.com, 42666, RESELLER sharethrough.com, QWxGEL6s, RESELLER, d53b998a7bd4ecd2 telaria.com, cpu32-92xut, RESELLER, 1a4e959a1b50034a tremorhub.com, cpu32-92xut, RESELLER, 1a4e959a1b50034a pubmatic.com, 156136, RESELLER, 5d62403b186f2ace google.com, pub-8221793852898543, RESELLER, f08c47fec0942fa0 google.com, pub-1968276357835282, RESELLER, f08c47fec0942fa0 risecodes.com, 64c7a4acd6298f0001a7d867, RESELLER smartadserver.com, 2951, RESELLER smartadserver.com, 3374, RESELLER appnexus.com, 1199, RESELLER, f5ab79cb980f11d1 rubiconproject.com, 22328, RESELLER, 0bfd66d529a55807 rubiconproject.com, 26184, RESELLER, 0bfd66d529a55807 adform.com, 2631, RESELLER, 9f5210a2f0999e32 indexexchange.com, 192051, RESELLER criteo.com, B-062041, RESELLER, 9fac4a4a87c2a44f dentsu.com, 71228, RESELLER lijit.com, 277115, RESELLER, fafdf38b16bf6b2b sharethrough.com, 1udopJ1S, RESELLER, d53b998a7bd4ecd2 lijit.com, 277115-eb, RESELLER, fafdf38b16bf6b2b contextweb.com, 558511, RESELLER inmobi.com, b01aa06531c543d8a5fb9982f60afb00, RESELLER, 83e75a7ae333ca9d aps.amazon.com, bbbb77a7-1459-4c85-af82-cd7e0a773a21, RESELLER improvedigital.com, 1062, RESELLER admanmedia.com, f85eeb2e, RESELLER smilewanted.com, 3834, RESELLER google.com, pub-9115524111147081, RESELLER, f08c47fec0942fa0 adyoulike.com, 0bce3861af1d6e06fbaaf13529e76b6e, RESELLER sharethrough.com, 98z2bw9f, RESELLER, d53b998a7bd4ecd2 indexexchange.com, 196713, RESELLER, 50b1c356f2c5c8fc indexexchange.com, 197617, RESELLER, 50b1c356f2c5c8fc pubmatic.com, 154037, RESELLER, 5d62403b186f2ace pubmatic.com, 156439, RESELLER, 5d62403b186f2ace pubmatic.com, 157841, RESELLER, 5d62403b186f2ace pubmatic.com, 160006, RESELLER, 5d62403b186f2ace pubmatic.com, 160842, RESELLER, 5d62403b186f2ace rubiconproject.com, 22330, RESELLER, 0bfd66d529a55807 rubiconproject.com, 16114, RESELLER, 0bfd66d529a55807 adpone.com, 1813bfe577448f6ef478, DIRECT contextweb.com, 562827, RESELLER, 89ff185a4c4e857c pubmatic.com, 159668, RESELLER, 5d62403b186f2ace richaudience.com, 06EhCbcfZK, DIRECT richaudience.com, quxufDBTNs, DIRECT lijit.com, 273644, RESELLER, fafdf38b16bf6b2b sunmedia.tv, 12918514-294e-4e6e-8eae-c89a8fec20f5, DIRECT, 24794F6 sunmedia.tv, 455be357-ad46-4f10-8872-701656980003, DIRECT, 24794F6 risecodes.com, 672ca0b2468a120001c76ef9, RESELLER smartadserver.com, 3820, RESELLER rubiconproject.com, 19668, RESELLER, 0bfd66d529a55807 appnexus.com, 7597, RESELLER, f5ab79cb980f11d1 openx.com, 540393169, RESELLER, 6a698e2ec38604c6 pubmatic.com, 160065, RESELLER, 5d62403b186f2ace google.com, pub-5617098146054077, RESELLER, f08c47fec0942fa0 pubmatic.com, 158055, RESELLER, 5d62403b186f2ace rubiconproject.com, 21506, RESELLER, 0bfd66d529a55807 Indexexchange.com, 190500, RESELLER smartadserver.com, 2776, RESELLER openx.com, 540362347, RESELLER, 6a698e2ec38604c6 freewheel.tv, 1133073, RESELLER aps.amazon.com, 3965, RESELLER improvedigital.com, 1552, RESELLER sunmedia.tv, 852c0d87-cafc-4bba-a88c-f74cf18086b0, DIRECT, 24794F6 33across.com, 0013300001kQj2HAAS, RESELLER, bbea06d9c4d2853c adform.com, 2865, RESELLER adyoulike.com, 7463c359225e043c111036d7a29affa5, RESELLER, 4ad745ead2958bf7 contextweb.com, 560288, RESELLER, 89ff185a4c4e857c contextweb.com, 562709, RESELLER, 89ff185a4c4e857c contextweb.com, 563115, RESELLER, 89ff185a4c4e857c kargo.com, 8824, RESELLER minutemedia.com, 01gya4708ddm, RESELLER openx.com, 559680764, RESELLER, 6a698e2ec38604c6 outbrain.com, 00f98002a95195662efb6f40c5311a76ff, RESELLER pubmatic.com, 158355, RESELLER, 5d62403b186f2ace rhebus.works, 5252004478, RESELLER adpone.com, ff4766b6846596df0816, DIRECT risecodes.com, 63832beef8189a00015cb6d3, RESELLER smartadserver.com, 4926, RESELLER telaria.com, lkiu7-jqvg1, RESELLER, 1a4e959a1b50034a themediagrid.com, 2LYG9A, RESELLER, 35d5010d7789b49d tremorhub.com, lkiu7-jqvg1, RESELLER, 1a4e959a1b50034a undertone.com, 4205, RESELLER, d954590d0cb265b9 admanmedia.com, 43, RESELLER admanmedia.com, 726, RESELLER criteo.com, B-060278, RESELLER, 9fac4a4a87c2a44f adyoulike.com, b4bf4fdd9b0b915f746f6747ff432bde, RESELLER adyoulike.com, 639201a8e0f88c543a4eadc792fb1058, RESELLER amxrtb.com, 105199649, RESELLER appnexus.com, 11786, RESELLER, f5ab79cb980f11d1 appnexus.com, 12290, RESELLER, f5ab79cb980f11d1 appnexus.com, 1356, RESELLER, f5ab79cb980f11d1 appnexus.com, 3703, RESELLER, f5ab79cb980f11d1 appnexus.com, 7664, RESELLER axonix.com, 57264, RESELLER beachfront.com, 14804, RESELLER, e2541279e8e2ca4d betweendigital.com, 44774, RESELLER contextweb.com, 562541, RESELLER, 89ff185a4c4e857c conversantmedia.com, 100435, RESELLER, 03113cd04947736d conversantmedia.com, 40915, RESELLER, 03113cd04947736d EMXDGT.com, 2481, RESELLER, 1e1d41537f7cad7f EMXDGT.com, 2009, RESELLER, 1e1d41537f7cad7f freewheel.tv, 1220655, RESELLER google.com, pub-1490961421801363, RESELLER, f08c47fec0942fa0 google.com, pub-1546102924523412, RESELLER, f08c47fec0942fa0 google.com, pub-1724616865008460, RESELLER, f08c47fec0942fa0 google.com, pub-5041886492880162, RESELLER, f08c47fec0942fa0 google.com, pub-5995202563537249, RESELLER, f08c47fec0942fa0 google.com, pub-8469965667274063, RESELLER, f08c47fec0942fa0 google.com, pub-9404419171574902, RESELLER, f08c47fec0942fa0 gumgum.com, 14141, RESELLER, ffdef49475d318a9 improvedigital.com, 1863, RESELLER improvedigital.com, 2050, RESELLER indexexchange.com, 186318, RESELLER indexexchange.com, 191503, RESELLER, 50b1c356f2c5c8fc indexexchange.com, 193091, RESELLER, 50b1c356f2c5c8fc indexexchange.com, 192410, RESELLER, 50b1c356f2c5c8fc lijit.com, 257429-eb, RESELLER, fafdf38b16bf6b2b lijit.com, 260380, RESELLER, fafdf38b16bf6b2b lijit.com, 408376, RESELLER, fafdf38b16bf6b2b lijit.com, 408376-eb, RESELLER, fafdf38b16bf6b2b lijit.com, 375328, RESELLER, fafdf38b16bf6b2b media.net, 8CUZ1MK22, RESELLER mintegral.com, 10043, RESELLER, 0aeed750c80d6423 mobfox.com, 45499, RESELLER mobfox.com, 74240, RESELLER onetag.com, 7a07370227fc000, RESELLER onetag.com, 770a440e65869c2, RESELLER openx.com, 537149888, RESELLER, 6a698e2ec38604c6 openx.com, 540274407, RESELLER, 6a698e2ec38604c6 openx.com, 540191398, RESELLER, 6a698e2ec38604c6 pubmatic.com, 156557, RESELLER pubmatic.com, 157362, RESELLER, 5d62403b186f2ace pubmatic.com, 160925, RESELLER, 5d62403b186f2ace pubmatic.com, 161527, RESELLER, 5d62403b186f2ace pubmatic.com, 157150, RESELLER, 5d62403b186f2ace pubmatic.com, 160096, RESELLER, 5d62403b186f2ace pubnative.net, 1006576, RESELLER, d641df8625486a7b rubiconproject.com, 18694, RESELLER, 0bfd66d529a55807 rubiconproject.com, 20736, RESELLER, 0bfd66d529a55807 rubiconproject.com, 20744, RESELLER, 0bfd66d529a55807 rubiconproject.com, 23844, RESELLER, 0bfd66d529a55807 rubiconproject.com, 18020, RESELLER, 0bfd66d529a55807 sharethrough.com, S6xYgb3B, RESELLER, d53b998a7bd4ecd2 sharethrough.com, 7144eb80, RESELLER, d53b998a7bd4ecd2 smaato.com, 1100044045, RESELLER, 07bcf65f187117b4 smaato.com, 1100047713, RESELLER, 07bcf65f187117b4 smaato.com, 1100044650, RESELLER, 07bcf65f187117b4 smartadserver.com, 3056, RESELLER smartadserver.com, 4111, RESELLER smartadserver.com, 4342, RESELLER smartadserver.com, 4125, RESELLER, 060d053dcf45cbf3 sonobi.com, 7f5fa520f8, RESELLER, d1a215d9eb5aee9e spotim.market, sp_AYL2022, RESELLER, 077e5f709d15bdbb themediagrid.com, RYIDPE, RESELLER, 35d5010d7789b49d themediagrid.com, JTQKMP, RESELLER, 35d5010d7789b49d triplelift.com, 12911-EB, RESELLER, 6c33edb13117fd86 xad.com, 958, RESELLER, 81cbf0a75a5e0e9a adform.com, 582, RESELLER, 9f5210a2f0999e32 rubiconproject.com, 20266, RESELLER, 0bfd66d529a55807 appnexus.com, 10736, RESELLER video.unrulymedia.com, 2564526802, RESELLER smartadserver.com, 4144, RESELLER nativo.com, 5848, RESELLER, 59521ca7cc5e9fee 33across.com, 0015a00003HljHyAAJ, RESELLER video.unrulymedia.com, 297618916, RESELLER xapads.com, 196344, RESELLER smartadserver.com, 1999-OB, RESELLER, 060d053dcf45cbf3 rtbdemand.com, 23110629672, DIRECT rubiconproject.com, 26890, RESELLER, 0bfd66d529a55807 pubmatic.com, 159855, RESELLER, 5d62403b186f2ace rubiconproject.com, 26884, RESELLER, 0bfd66d529a55807 152media.info, 152M21, RESELLER openx.com, 539848768, RESELLER, 6a698e2ec38604c6 pixfuture.com, 10390, DIRECT openx.com, 540406323, RESELLER, 6a698e2ec38604c6 openx.com, 545702544, RESELLER, 6a698e2ec38604c6 pubmatic.com, 158127, DIRECT, 5d62403b186f2ace pubmatic.com, 159775, DIRECT, 5d62403b186f2ace sonobi.com, 0b24fdfc82, DIRECT, d1a215d9eb5aee9e sharethrough.com, 62beb9db, DIRECT, d53b998a7bd4ecd2 sharethrough.com, izM1hGJl, DIRECT, d53b998a7bd4ecd3 d-sail.com, ds0453, DIRECT google.com, pub-2205121062140812, RESELLER, f08c47fec0942fa0 33across.com, 0010b00002VYZoUAAX, DIRECT, bbea06d9c4d2853c appnexus.com, 10239, RESELLER, f5ab79cb980f11d1 adtelligent.com, 500592, DIRECT sovrn.com, 331050, DIRECT, fafdf38b16bf6b2b rubiconproject.com, 23564, DIRECT, 0bfd66d529a55807 rubiconproject.com, 23564, RESELLER, 0bfd66d529a55807 media.net, 8CUIUMTP7, DIRECT e-planning.net, 29459e615aaa9065, DIRECT, c1ba615865ed87b2 themediagrid.com, QDC97I, DIRECT, 35d5010d7789b49d onetag.com, 79c9089f60042c0, DIRECT adyoulike.com, 16b87fd2fa41ddc6e584a7ef30df0eb3, DIRECT, 4ad745ead2958bf7 mgid.com, 130961, DIRECT, d4c29acad76ce94f conversantmedia.com, 42037, DIRECT, 03113cd04947736d smartyads.com, 20133, DIRECT, fd2bde0ff2e62c5d smilewanted.com, 5329, RESELLER nobid.io, 120605, DIRECT yahoo.com, 57289, RESELLER, e1a5b5b6e3255540 rhythmone.com, 2439829435, RESELLER, a670c89d4a324e47 xandr.com, 11429, DIRECT, f5ab79cb980f11d1 xandr.com, 12701, DIRECT, f5ab79cb980f11d1 rhythmone.com, 3736557092, RESELLER, a670c89d4a324e47 nativo.com, 5677, DIRECT admanmedia.com, 812, DIRECT indexexchange.com, 195491, RESELLER, 50b1c356f2c5c8fc gumgum.com, 13753, RESELLER, ffdef49475d318a9 nextmillennium.io, 17000, DIRECT, 65bd090fa4a1e3d6 admagnetix.io, 202021, DIRECT nextmillennium.io, 16119, DIRECT, 65bd090fa4a1e3d6 admagnetix.io, 201119, DIRECT gannett.com, 23033711203, DIRECT appnexus.com, 9284, DIRECT, f5ab79cb980f11d1 appnexus.com, 15799, DIRECT, f5ab79cb980f11d1 rubiconproject.com, 17888, RESELLER, 0bfd66d529a55807 rubiconproject.com, 26296, RESELLER, 0bfd66d529a55807 pubmatic.com, 157577, DIRECT, 5d62403b186f2ace pubmatic.com, 164400, RESELLER, 5d62403b186f2ace indexexchange.com, 194648, RESELLER, 50b1c356f2c5c8fc indexexchange.com, 207985, RESELLER, 50b1c356f2c5c8fc openx.com, 540224251, DIRECT, 6a698e2ec38604c6 openx.com, 540225743, DIRECT, 6a698e2ec38604c6 33across.com, 0010b00002e4MRRAA2, DIRECT, bbea06d9c4d2853c 33across.com, 001Pg000007PnplIAC, DIRECT, bbea06d9c4d2853c #33Across #hb #tag yieldmo.com, 2230523609997805235, DIRECT rubiconproject.com, 10968, RESELLER, 0bfd66d529a55807 aps.amazon.com,b3d50ad3-eca1-4091-be72-de4a8bc67a3d,DIRECT emxdgt.com,1336,DIRECT,1e1d41537f7cad7f appnexus.com,1356,RESELLER,f5ab79cb980f11d1 appnexus.com,1908,RESELLER,f5ab79cb980f11d1 districtm.io,100428,DIRECT,3fd707be9c4527c3 indexexchange.com,192410,RESELLER,50b1c356f2c5c8fc openx.com,540191398,RESELLER,6a698e2ec38604c6 ad-generation.jp,12474,RESELLER,7f4ea9029ac04e53 gumgum.com,14141,RESELLER,ffdef49475d318a9 admanmedia.com,726,RESELLER sharethrough.com,7144eb80,RESELLER,d53b998a7bd4ecd2 emxdgt.com,2009,RESELLER,1e1d41537f7cad7f contextweb.com,562541,RESELLER,89ff185a4c4e857c themediagrid.com,JTQKMP,RESELLER,35d5010d7789b49d sovrn.com,276595,DIRECT,fafdf38b16bf6b2b lijit.com,276595,DIRECT,fafdf38b16bf6b2b beachfront.com,14804,RESELLER,e2541279e8e2ca4d mintegral.com,10043,RESELLER,0aeed750c80d6423 sonobi.com,7f5fa520f8,RESELLER,d1a215d9eb5aee9e onetag.com,62e564782c44a66,DIRECT media.net,8CUZ1MK22,RESELLER smaato.com,1100053606,DIRECT,07bcf65f187117b4 risecodes.com,63832beef8189a00015cb6d3,RESELLER uis.mobfox.com,93308,RESELLER,5529a3d1f59865be mediago.io,045ac24b888bcf59a09731e7f0f2084f,RESELLER adyoulike.com,7463c359225e043c111036d7a29affa5,RESELLER minutemedia.com,01gya4708ddm,RESELLER visiblemeasures.com,1052,RESELLER undertone.com,4205,RESELLER,d954590d0cb265b9 kargo.com,8824,RESELLER start.io,123111883,RESELLER video.unrulymedia.com,612539011,DIRECT,a670c89d4a324e47 connectad.io,455,RESELLER,85ac85a30c93b3e5 onlinemediasolutions.com,21020,RESELLER,b3868b187e4b6402 supply.colossusssp.com,836,RESELLER,6c5b49d96ec1b458 opera.com,pub12058951686464,RESELLER,55a0c5fd61378de3 rubiconproject.com,27408,DIRECT,0bfd66d529a55807 richaudience.com,1fsNorHWpU,DIRECT didna.io, 494n1p17180a, DIRECT thegermanemedia.com, 771, DIRECT 33across.com, 001Pg00001FifW9IAJ, DIRECT, bbea06d9c4d2853c inmobi.com, b874aa097f3d43ffadc51642ffd3999c, RESELLER, 83e75a7ae333ca9d lijit.com, 509119, DIRECT, fafdf38b16bf6b2b pubmatic.com, 166855, RESELLER, 5d62403b186f2ace smartadserver.com, 4938, RESELLER, 060d053dcf45cbf3 smartadline.com, 22843771578, DIRECT smartadline.com, 23325730296, DIRECT aps.amazon.com, d4004b5f-4fb6-4be2-82ae-0e36b8f52c12, DIRECT pubmatic.com, 162914, RESELLER, 5d62403b186f2ace rubiconproject.com, 25512, RESELLER, 0bfd66d529a55807 appnexus.com, 15686, DIRECT, f5ab79cb980f11d1 rubiconproject.com, 27410, DIRECT, 0bfd66d529a55807 nobid.io, 22486896825, DIRECT kulture.media, 9533, DIRECT rubiconproject.com, 26094, DIRECT video.unrulymedia.com, 946176315, DIRECT pubmatic.com, 162418, RESELLER, 5d62403b186f2ace xandr.com, 14246, RESELLER rubiconproject.com, 13380, RESELLER, 0bfd66d529a55807 minutemedia.com, 01gcrv9grwe9, RESELLER appnexus.com, 8381, RESELLER triplelift.com, 6030, RESELLER, 6c33edb13117fd86 sharethrough.com, aRE1degH, RESELLER, d53b998a7bd4ecd2 richaudience.com, 6u2dr79SGJ, RESELLER smilewanted.com, 5514, RESELLER Cue7ven.com,783517,RESELLER flashb.id, 22a897ca-8cd1-59a3-b4d5-a3cd7a23486b, DIRECT rubiconproject.com, 20922, RESELLER, 0bfd66d529a55807 smartadserver.com, 3389, RESELLER, 060d053dcf45cbf3 openx.com, 559913615, RESELLER, 6a698e2ec38604c6 sharethrough.com, 332baa08, RESELLER, d53b998a7bd4ecd2 onetag.com, 5cca11704094eb8, RESELLER adyoulike.com, bcf6c423bc90ec180005086dd9935a1b, RESELLER risecodes.com, 65b9125633dab2000102902c, RESELLER appnexus.com, 11701, RESELLER adform.com, 3125, RESELLER smilewanted.com, 2457, RESELLER video.unrulymedia.com, 273421059, RESELLER triplelift.com, 12738, RESELLER, 6c33edb13117fd86 152media.info, 152M33, RESELLER media.net, 8CUJ8C82U, RESELLER improvedigital.com, 2154, RESELLER lijit.com, 447882, RESELLER, fafdf38b16bf6b2b freewheel.tv, 1602344, RESELLER freewheel.tv, 1602346, RESELLER rubiconproject.com, 17250, RESELLER, 0bfd66d529a55807 appnexus.com, 11664, RESELLER rubiconproject.com, 24482, DIRECT, 0bfd66d529a55807 google.com , pub-5413329544040947, RESELLER, f08c47fec0942fa0 google.com, pub-3328898302928686, RESELLER, f08c47fec0942fa0 biddo.net , bdc-6502, DIRECT google.com , pub-3328898302928686, RESELLER, f08c47fec0942fa0 biddo.net, bdc-6502, DIRECT google.com, pub-3328898302928686, RESELLER, f08c47fec0942fa0 google.com, pub-8699255262206653, RESELLER, f08c47fec0942fa0 | C2: pubmatic.com, 156107, RESELLER, 5d62403b186f2ace auxoads.com, 5c451286d555ce7ce6dc3204f1e37959, DIRECT rubiconproject.com,22554, RESELLER, 0bfd66d529a55807 google.com, pub-1781853254296294, DIRECT, f08c47fec0942fa0 google.com, pub-4305474543250232, DIRECT, f08c47fec0942fa0 google.com, pub-4964914015319876, DIRECT, f08c47fec0942fa0 pubmatic.com, 159855, DIRECT, 5d62403b186f2ace rubiconproject.com, 24484, DIRECT, 0bfd66d529a55807 pubmatic.com, 163761, RESELLER, 5d62403b186f2ace rubiconproject.com, 22554, RESELLER, 0bfd66d529a55807 auxoads.com, 427b1009, DIRECT pubmatic.com, 166212, RESELLER, 5d62403b186f2ace biddigi.com, ADG521, DIRECT programmaticians.com, PGADG521, DIRECT rightxchange.com, REXADG521, DIRECT auxoads.com, 8f5dab940481b8aea4c622326b9e020c, DIRECT rtbdemand.com, 23041948471, DIRECT incrementx.com,60106,DIRECT, 8728b7e97e589da4 adform.com, 3033, RESELLER, 9f5210a2f0999e32 onetag.com, 46218987a9da2b5-OB, DIRECT biddo.net, bdc-4939, DIRECT invamia.com, ivm-4939, DIRECT vidverto.com, vdvt-4939, DIRECT video.unrulymedia.com, 888848102, RESELLER biddigi.com, ADG521, DIRECT programmaticians.com, PGADG521, DIRECT | D2: =VLOOKUP(A2,'Account Managers List'!D:F,2,FALSE) -> Pernika | G2: google.com, pub-7094677798399606, RESELLER, f08c47fec0942fa0
